<?xml version="1.0"?>
<robot name="simple_robot">

  <!-- Link utama robot -->
  <link name="base_link"/>

  <!-- Roda robot -->
  <link name="front_left_wheel"/>
  <link name="front_right_wheel"/>
  <link name="back_left_wheel"/>
  <link name="back_right_wheel"/>

  <!-- Sensor Kamera -->
  <link name="camera_link"/>

  <!-- Joint untuk menghubungkan roda ke robot -->
  <joint name="front_left_wheel_joint" type="revolute">
    <parent link="base_link"/>
    <child link="front_left_wheel"/>
    <origin xyz="-0.2 0.2 0.1"/>
    <axis xyz="0 0 1"/>
    <limit effort="50.0" velocity="1.0" lower="0" upper="2.0"/>
  </joint>

  <joint name="front_right_wheel_joint" type="revolute">
    <parent link="base_link"/>
    <child link="front_right_wheel"/>
    <origin xyz="-0.2 -0.2 0.1"/>
    <axis xyz="0 0 1"/>
    <limit effort="50.0" velocity="1.0" lower="0" upper="2.0"/>
  </joint>

  <joint name="back_left_wheel_joint" type="revolute">
    <parent link="base_link"/>
    <child link="back_left_wheel"/>
    <origin xyz="0.2 0.2 0.1"/>
    <axis xyz="0 0 1"/>
    <limit effort="50.0" velocity="1.0" lower="0" upper="2.0"/>
  </joint>

  <joint name="back_right_wheel_joint" type="revolute">
    <parent link="base_link"/>
    <child link="back_right_wheel"/>
    <origin xyz="0.2 -0.2 0.1"/>
    <axis xyz="0 0 1"/>
    <limit effort="50.0" velocity="1.0" lower="0" upper="2.0"/>
  </joint>

  <!-- Kamera -->
  <joint name="camera_joint" type="fixed">
    <parent link="base_link"/>
    <child link="camera_link"/>
    <origin xyz="0 0 0.5"/>
  </joint>

  <gazebo>
    <sensor name="camera" type="camera">
      <pose>0 0 0.5 0 0 0</pose>
      <camera>
        <horizontal_fov>1.5708</horizontal_fov>
        <image_width>640</image_width>
        <image_height>480</image_height>
        <update_rate>30</update_rate>
      </camera>
    </sensor>
  </gazebo>
</robot>

